Workbook

Sheet Sopas
A1: Plato | B1: Página | C1: Elaboración | D1: Ingredientes | E1: Cantidades | F1: Unidades
A2: Salmorejo con guindillas fritas | B2: 185 | C2: Lava los tomates, trocéalos, colócalos en un vaso americano y tritúralos bien. Cuela el puré y ponlo de nuevo en el vaso americano. Agrega la miga de pan (troceada), el diente de ajo (pelado), sal (al gusto) y 100 ml de aceite. Tritura todo bien hasta conseguir una crema homogénea. Pasa el salmorejo a una jarra, introdúcelo en el frigorífico y deja que se enfríe bien. Calienta abundante aceite en una sartén. Cuando esté bien caliente, añade las guindillas y fríelas durante 2 minutos por cada lado. Retíralas a un plato y sazónalas. Sirve el salmorejo en cuatro platos y reparte encima (a un lado) las guindillas. Decora los platos con unas hojas de perejil. | D2: Tomate pera | E2: 1000 | F2: g
D3: Guindilla | E3: 300 | F3: g
D4: Miga de pan | E4: 100 | F4: g
D5: Diente de ajo | E5: 1 | F5: uds
D6: Aceite de oliva | E6: 1 | F6: uds
D7: Perejil | E7: 1 | F7: uds
D8: Sal | E8: 1 | F8: uds
A9: Sopa de cocido con tapioca | B9: 190 | C9: Pon los garbanzos a remojo la víspera. Escurre los garbanzos y colócalos en una red. Pon a calentar 2 litros de agua en una olla rápida. Añade unas ramas de perejil, el muslo de pollo, el zancarrón, los huesos, el puerro (limpio y troceado), la cebolleta (pelada y troceada) y los dientes de ajo (pelados). Cuando el agua esté caliente, introduce los garbanzos, sazona, cierra la olla y cuece todo durante 20-25 minutos. Retira las hortalizas, las carnes y los huesos. Cuela el caldo, desgrásalo y resérvalo. Pica las carnes y resérvalas. Saca el tuétano de los huesos, unta con él las rebanadas de pan y sazónalas. Pon el caldo a calentar. Cuando empiece a hervir, añade la tapioca y cuécela durante el tiempo que indique el paquete. Agrega la mitad de los garbanzos (reserva el resto para otra ocasión), las carnes (pollo y zancarrón) picadas y un poco de perejil picado. Reparte la sopa en 4 platos hondos, acompáñalos con las tostadas con tuétano y adórnalos con unas hojas de perejil. | D9: Garbanzos | E9: 200 | F9: g
D10: Muslo de pollo | E10: 1 | F10: uds
D11: Zancarrón | E11: 250 | F11: g
D12: Hueso de cañada | E12: 4 | F12: uds
D13: Puerro | E13: 1 | F13: uds
D14: Cebolla | E14: 1 | F14: uds
D15: Diente de ajo | E15: 2 | F15: uds
D16: Picatostes | E16: 1 | F16: uds
D17: Tapioca | E17: 50 | F17: g
D18: Perejil | E18: 1 | F18: uds
D19: Sal | E19: 1 | F19: uds
A20: Sopa de udon con pollo | B20: 205 | C20: Maja en el mortero los ajos (pelados), incorpora la pimienta, las hojas de cilantro y una pizca de sal y maja todo. Agrega el vinagre y la salsa de soja, mezcla y reserva. Calienta una cazuela con 2-3 cucharadas de aceite. Corta la cebolleta en dados, añádela a la cazuela y ponla a rehogar a fuego suave. Limpia el puerro, córtalo en cuartos de luna y añádelo. Pela la zanahoria, córtala de la misma manera e incorpórala. Retira el tallo y las semillas del pimiento verde, córtalo en dados y agrégalo. Pela el pimiento rojo, córtalo en dados y añádelo. Lava la rama de apio, córtala en dados e incorpórala. Sazona y cocina las hortalizas a fuego suave durante unos 5 minutos. Retira las hortalizas, pásalas a una fuente y resérvalas. Agrega 1 cucharada más de aceite a la cazuela. Corta la pechuga de pollo en dados, sazónala, añádela a la cazuela y rehógala hasta que se dore. Agrega las hortalizas reservadas, cúbrelas con abundante agua y desmenuza encima la pastilla de caldo. Incorpora el udón y el majado. Ralla encima un poco de nuez moscada y cocina todo durante 7-8 minutos. Reparte la sopa en platos hondos y decóralos con unas hojas de perejil. | D20: Fideos udon | E20: 150 | F20: g
D21: Pechuga de pollo | E21: 0.5 | F21: uds
D22: Diente de ajo | E22: 2 | F22: uds
D23: Salsa de soja | E23: 50 | F23: mL
D24: Cebolla | E24: 1 | F24: uds
D25: Puerro | E25: 0.5 | F25: uds
D26: Zanahoria | E26: 1 | F26: uds
D27: Pimiento verde | E27: 1 | F27: uds
D28: Pimiento rojo | E28: 0.5 | F28: uds
D29: Rama de apio | E29: 1 | F29: uds
D30: Pastilla de caldo de pollo | E30: 1 | F30: uds
D31: Aceite de oliva | E31: 1 | F31: uds
D32: Vinagre blanco | E32: 30 | F32: mL
... D37: Sal | E37: 1 | F37: uds

Sheet Cremas
A1: =Sopas!A1 -> Plato | B1: Página | C1: Elaboración | D1: =Sopas!D1 -> Ingredientes | E1: =Sopas!E1 -> Cantidades | F1: =Sopas!F1 -> Unidades
A2: Crema de calabacín | B2: 166 | C2: Pela la cebolla, retira el tallo y las semillas del pimiento, córtalos en dados y ponlos a rehogar en una cazuela con 2-3 cucharadas de aceite. Limpia bien los calabacines, corta ½ calabacín en dados y resérvalo. Corta el resto en cuartos de luna e incorpóralos a la cazuela. Rehoga durante 4-5 minutos y agrega el caldo y el arroz. Salpimienta y cuece todo durante 20-25 minutos. Mientras tanto, calienta 2 cucharadas de aceite en una sartén y saltea en ella los dados de calabacín. Resérvalos. Corta las láminas de pasta brick en 4, pon una pequeña porción de huevas sobre cada trozo y envuélvelas hasta conseguir 8 paquetitos. Fríelos por los dos lados en una sartén con abundante aceite caliente, retíralos, escúrrelos sobre un plato cubierto con papel absorbente y resérvalos. Retira del fuego la cazuela con las hortalizas y el arroz y tritura todo con una batidora eléctrica. Incorpora la leche evaporada y mezcla bien. Reparte la crema y los dados de calabacín en 4 platos hondos. Acompaña las cremas con los paquetitos de pasta brick y adorna los platos con unas hojas de perejil. | D2: Calabacín | E2: 2 | F2: uds
D3: Cebolla | E3: 1 | F3: uds
D4: Pimiento verde | E4: 1 | F4: uds
D5: Caldo de verduras | E5: 1500 | F5: mL
D6: Arroz | E6: 4 | F6: cuch
D7: Láminas de pasta brick | E7: 2 | F7: uds
D8: Leche evaporada | E8: 125 | F8: mL
D9: Huevas de trucha | E9: 100 | F9: g
D10: Aceite de oliva | E10: 1 | F10: uds
D11: Perejil | E11: 1 | F11: uds
D12: Pimienta | E12: 1 | F12: uds
D13: Sal | E13: 1 | F13: uds
A14: Sopa fría de zanahoria | B14: 177 | C14: Calienta 1.250 ml de agua en una olla rápida. Pela las zanahorias, introdúcelas en la olla, sazónalas, cierra la olla y cuécelas durante 4 minutos. Retíralas, escúrrelas y deja que se enfríen. Reserva por separado el agua de la cocción. Trocea las zanahorias y ponlas en el vaso americano, agrega la manzana (pelada y troceada), el comino, parte del agua de la cocción (según tus preferencias: más ligera o más espesa) y el vinagre. Tritura todo hasta conseguir una crema homogénea. Añade el aceite poco a poco y sigue triturando hasta que emulsione. Pon a punto de sal, introduce la sopa en el frigorífico y deja que se enfríe bien. Para preparar la guarnición, corta la cebolleta, el pimiento y el jamón en daditos, y los tomates, en cuartos. Reparte la sopa en 4 platos hondos, salpica los platos con la guarnición y decóralos con unas hojas de perejil. | D14: Zanahoria | E14: 800 | F14: g
D15: Manzana | E15: 1 | F15: uds
D16: Cebolla | E16: 0.5 | F16: uds
D17: Pimiento verde | E17: 0.5 | F17: uds
D18: Jamón | E18: 100 | F18: g
D19: Tomate pera | E19: 1 | F19: uds
D20: Vinagre | E20: 1 | F20: cuch
D21: Aceite de oliva | E21: 50 | F21: mL
D22: Perejil | E22: 1 | F22: uds
D23: Comino | E23: 0.25 | F23: cuch
D24: Sal | E24: 1 | F24: uds

Sheet Verduras
A1: =Sopas!A1 -> Plato | B1: Página | C1: Elaboración | D1: =Sopas!D1 -> Ingredientes | E1: =Sopas!E1 -> Cantidades | F1: =Sopas!F1 -> Unidades
A2: Albóndigas de hortalizas | B2: 214 | C2: Lava las patatas, ponlas en una cazuela, cúbrelas con agua y cuécelas durante 30-35 minutos (contados desde el momento en que el agua empiece a hervir). Retíralas y deja que se templen. Para la salsa, calienta una cazuela con 3 cucharadas de aceite. Pela 2 dientes de ajo y la cebolla, córtalos en dados y añádelos a la cazuela. Retira la parte inferior, superior y 2-3 capas del puerro, lávalo, córtalo en cuartos de luna e incorpóralo a la cazuela. Pela 2 zanahorias, córtalas de la misma manera y agrégalas. Sazona y cocina las hortalizas a fuego suave-medio durante 15 minutos. Agrega la cucharada de harina y rehógala bien. Vierte encima el vino y dale un hervor. Añade 300 ml de agua y cocina todo durante 10 minutos. Tritura con una batidora eléctrica hasta conseguir una salsa homogénea. Resérvala y caliéntala un poco en el momento de servir. Lava el calabacín, córtalo en daditos y ponlo a rehogar en una sartén con 3 cucharadas de aceite. Pela la otra zanahoria, rállala y agrégala. Pela el otro diente de ajo, córtalo en daditos e incorpóralo. Sazona y cocina las hortalizas a fuego suave-medio durante 10 minutos. Escúrrelas bien y resérvalas. Pela las patatas, ponlas en un bol y aplástalas con un machacador de patatas. Sazónalas, agrega las hortalizas (calabacín, zanahoria y ajo) escurridas y mezcla bien. Añade el pan rallado poco a poco, sin dejar de mezclar, hasta conseguir una masa homogénea. Coge pequeñas porciones de masa, redondéalas y forma las albóndigas. Pásalas por harina y fríelas en una sartén con abundante aceite. Escúrrelas sobre una fuente cubierta con papel absorbente. Sirve la salsa en la base de los platos y coloca encima 3-4 albóndigas. Decora los platos con polvo de perejil y unas hojas de perejil. | D2: Patata | E2: 2 | F2: uds
D3: Calabacín | E3: 1 | F3: uds
D4: Zanahoria | E4: 3 | F4: uds
D5: Diente de ajo | E5: 3 | F5: uds
D6: Cebolla | E6: 1 | F6: uds
D7: Puerro | E7: 1 | F7: uds
D8: Harina | E8: 1 | F8: cuch
D9: Vino blanco | E9: 100 | F9: mL
D10: Pan rallado | E10: 50 | F10: g
D11: Harina | E11: 1 | F11: uds
D12: Aceite de oliva | E12: 1 | F12: uds
D13: Perejil | E13: 1 | F13: uds
D14: Sal | E14: 1 | F14: uds
A15: Berenjenas rellenas con bechamel de queso azul | B15: 224 | C15: Calienta una cazuela grande con abundante agua y sazónala. Corta las berenjenas por la mitad a lo largo, agrégalas y cuécelas durante 15 minutos. Retíralas, escúrrelas, sécalas bien y vacíalas sin romperles la piel. Corta la pulpa en daditos y resérvala. Reserva también las 4 cáscaras. Pela los dientes de ajo y córtalos en daditos. Pela la zanahoria y córtala del mismo modo. Lava el pimiento, retírale el tallo y las semillas y córtalo también en daditos. Pon las hortalizas a rehogar en una sartén con 3 cucharadas de aceite, sazónalas y cocínalas durante 6-8 minutos. Pica la carne de pavo, salpimiéntala, incorpórala a la sartén y cocínala brevemente. Agrega la pulpa de las berenjenas y cocina conjuntamente durante 5 minutos. Rellena las cáscaras de berenjena con la farsa y resérvalas. Para preparar la bechamel, calienta el aceite, añade la harina y cocínala un poco. Agrega la leche poco a poco, sin dejar de remover hasta que los ingredientes queden bien integrados. Sazona y cocina la bechamel durante 6-8 minutos sin dejar de remover. Cuando esté casi a punto, añade el queso azul y cocina hasta que quede integrado en la bechamel. Napa las berenjenas con la bechamel de queso, introdúcelas en el horno y gratínalas (3-5 minutos) hasta que se doren. Sirve media berenjena en cada plato y adórnalos con unas hojas de perejil. | D15: Berenjena | E15: 2 | F15: uds
D16: Diente de ajo | E16: 3 | F16: uds
D17: Zanahoria | E17: 1 | F17: uds
D18: Pimiento verde | E18: 1 | F18: uds
D19: Pechuga de pavo | E19: 300 | F19: g
D20: Aceite de oliva | E20: 1 | F20: uds
D21: Perejil | E21: 1 | F21: uds
D22: Pimienta | E22: 1 | F22: uds
D23: Sal | E23: 1 | F23: uds
D24: Queso azul | E24: 100 | F24: g
D25: Harina | E25: 30 | F25: g
D26: Leche | E26: 350 | F26: mL
D27: Aceite de oliva | E27: 2 | F27: cuch
D28: Sal | E28: 1 | F28: uds
A29: Pastel de patatas, jamón cocido y panceta | B29: 254 | C29: Casca los huevos y ponlos en un bol. Agrega la leche y un poco de perejil picado y salpimienta. Pela las patatas cocidas, trocéalas y añádelas. Mezcla bien y reserva. Corta la panceta y el jamón en dados y saltéalos en una sartén con 2 cucharadas de aceite. Retíralos, escúrrelos y añádelos al bol de los huevos con patata. Unta un molde con mantequilla y espolvoréalo con un poco de harina. Vierte en él la mezcla anterior y hornea a 180 ºC durante 30 minutos. Retira el pastel y deja que se temple un poco. Desmolda el pastel, sírvelo y acompáñalo con la salsa de tomate. Adorna los platos con unas hojas de perejil. | D29: Patata | E29: 4 | F29: uds
D30: Jamón cocido | E30: 150 | F30: g
D31: Panceta | E31: 150 | F31: g
D32: Huevo | E32: 5 | F32: uds
D33: Leche | E33: 150 | F33: mL
D34: Mantequilla | E34: 1 | F34: uds
D35: Harina | E35: 1 | F35: uds
D36: Tomate frito | E36: 250 | F36: mL
D37: Aceite de oliva | E37: 1 | F37: uds
D38: Perejil | E38: 1 | F38: uds
D39: Pimienta | E39: 1 | F39: uds
D40: Sal | E40: 1 | F40: uds
...

Sheet Legumbres
A1: =Sopas!A1 -> Plato | B1: Página | C1: Elaboración | D1: =Sopas!D1 -> Ingredientes | E1: =Sopas!E1 -> Cantidades | F1: =Sopas!F1 -> Unidades
A2: Alubias blancas con butifarra | B2: 291 | C2: La víspera, pon las alubias blancas en un bol grande, cúbrelas con agua, introdúcelas en el frigorífico y déjalas a remojo. Escúrrelas, ponlas en una olla rápida y cúbrelas con agua. Limpia el puerro (retírale la parte inferior, la superior y la primera capa y enjuágalo), córtalo en 3-4 trozos y ponlo en una red de cocer legumbres. Pela la cebolla y agrégala a la red. Cierra la red e introdúcela en la olla junto con el laurel. Sazona, cierra la olla y cuece las alubias durante 3 minutos. Escurre las alubias y resérvalas. En el momento de servir, saca las hortalizas de la red, córtalas un poco y ponlas en una fuente. Sazónalas y riégalas con un chorrito de aceite. Calienta una sartén grande con 3 cucharadas de aceite. Pincha las butifarras con una puntilla (cuchillo pequeño), colócalas en la sartén y cocínalas a fuego medio durante 3-4 minutos por cada lado. Retíralas y resérvalas en un plato. A la hora de servir, córtalas en rodajas gruesas. Agrega las alubias escurridas a la sartén donde has cocinado las butifarras y saltéalas durante 2 minutos. Sirve en cada plato una buena porción de alubias y unas rodajas de butifarra. Acompaña con el puerro y la cebolla y adorna los platos con unas hojas de perejil. | D2: Alubias blancas | E2: 400 | F2: g
D3: Butifarra blanca | E3: 4 | F3: g
D4: Puerro | E4: 1 | F4: uds
D5: Cebolla | E5: 1 | F5: uds
D6: Aceite de oliva | E6: 1 | F6: uds
D7: Laurel | E7: 2 | F7: uds
D8: Perejil | E8: 1 | F8: uds
D9: Sal | E9: 1 | F9: uds
A10: Chícaros con codillo | B10: 296 | C10: Calienta 3-4 cucharadas de aceite en una olla rápida. Pela los dientes de ajo, córtalos en dados y añádelos a la olla. Pela la cebolla, córtala en daditos y agrégala. Retira el tallo y las semillas del pimiento, córtalo de la misma manera e incorpóralo. Sazona y cocina las hortalizas a fuego suave durante 10 minutos. Agrega la salsa de tomate y cocina durante 4-5 minutos más. Calienta 1 cucharada de aceite en una sartén. Corta los chorizos en rodajas y la panceta en trozos de 1 cm, añádelos a la sartén y dóralos bien. Incorpóralos (sin grasa) a la olla. Pela la calabaza y córtala en trozos de bocado. Pela las patatas y trocéalas (cascándolas). Agrégalas (calabaza y patatas) a la olla. Añade también los chícharos, el codillo, el laurel, el pimentón y el comino. Cubre todo con agua, cierra la olla y cocina los ingredientes a fuego suave-medio durante 15 minutos. Abre la olla, retira el codillo y córtalo en 6 trozos. Reparte el guiso en 6 platos y pon un trozo de codillo en cada uno. Adórnalos con unas hojas de perejil. | D10: Chícharos | E10: 400 | F10: g
D11: Codillo de cerdo | E11: 1 | F11: uds
D12: Diente de ajo | E12: 5 | F12: uds
D13: Cebolla | E13: 1 | F13: uds
D14: Pimiento verde | E14: 1 | F14: uds
D15: Tomate frito | E15: 100 | F15: mL
D16: Chorizo | E16: 2 | F16: uds
D17: Panceta | E17: 100 | F17: g
D18: Calabaza | E18: 250 | F18: g
D19: Patata | E19: 2 | F19: uds
D20: Aceite de oliva | E20: 1 | F20: uds
D21: Laurel | E21: 1 | F21: uds
D22: Perejil | E22: 1 | F22: uds
... D25: Sal | E25: 1 | F25: uds
A26: Lentejas con chorizo y panceta | B26: 300 | C26: Pon la panceta en una olla rápida, cúbrela con agua, sazónala, cierra la olla y cuécela durante 30 minutos. Retírala y deja que se enfríe. Calienta 2-3 cucharadas de aceite en una cazuela. Pela la cebolleta y la zanahoria y limpia bien el puerro (retírale la parte inferior, la superior y 1-2 capas de hojas y enjuágalo). Corta la cebolleta en dados, y la zanahoria y el puerro, en cuartos de luna finos. Agrega las hortalizas a la cazuela, sazónalas y cocínalas a fuego suave-medio durante 8-10 minutos. Corta el chorizo en 4 trozos e incorpóralo a la cazuela. Agrega las lentejas, cúbrelas con abundante agua (3-4 veces más que de lentejas), sazónalas y cuécelas a fuego suave durante 40-45 minutos. Añade el pimentón y mezcla bien. Calienta una sartén sin aceite. Corta la panceta en 4 trozos, ponlos en la sartén y dóralos por los dos lados. Sirve las lentejas con chorizo en 4 platos y coloca un trozo de panceta en cada uno. Adorna los platos con unas hojas de perejil. | D26: Lentejas | E26: 300 | F26: g
D27: Chorizo | E27: 100 | F27: g
D28: Panceta | E28: 200 | F28: g
D29: Cebolla | E29: 1 | F29: uds
D30: Zanahoria | E30: 1 | F30: uds
D31: Puerro | E31: 1 | F31: uds
D32: Aceite de oliva | E32: 1 | F32: uds
D33: Perejil | E33: 1 | F33: uds
D34: Pimentón | E34: 0.5 | F34: cuch
D35: Sal | E35: 1 | F35: uds
A36: Alubias con panceta asada | B36: 302 | C36: Sazona la panceta, colócala en un recipiente apto para el horno, riégala con un chorro de aceite y ásala en el horno a 170 ºC durante 30 minutos. Sube la temperatura a 190 ºC y hornéala durante otros 10 minutos más. Retírala y córtala en 4 trozos. Pela la cebolleta y córtala en daditos. Limpia los puerros (retirándoles la parte inferior, la superior y 1-2 capas), enjuágalos bien y córtalos en daditos. Pela la zanahoria y córtala de la misma manera. Calienta 2 cucharadas de aceite en una olla rápida, agrega las hortalizas, sazónalas y rehógalas durante 10 minutos. Pela el tomate, pícalo finamente e incorpóralo. Cocina conjuntamente durante 6-8 minutos. Agrega las alubias, cúbrelas con agua y sazónalas. Tapa y cierra la olla y cuécelas durante unos 15 minutos. Calienta agua en una cazuela, introduce en ella la morcilla y cuécela a fuego suave durante 30 minutos (15 por cada lado). Retírala y córtala en 4 trozos. Reparte las alubias en 4 platos y pon encima de cada uno 1 trozo de morcilla y 1 trozo de panceta. Decora los platos con unas hojas de perejil. | D36: Alubias negras | E36: 300 | F36: g
D37: Panceta | E37: 250 | F37: g
D38: Cebolla | E38: 1 | F38: uds
D39: Puerro | E39: 2 | F39: uds
D40: Zanahoria | E40: 1 | F40: uds
D41: Tomate | E41: 1 | F41: uds
D42: Morcilla de verduras | E42: 1 | F42: uds
...

Sheet Huevos
A1: =Sopas!A1 -> Plato | B1: Página | C1: Elaboración | D1: =Sopas!D1 -> Ingredientes | E1: =Sopas!E1 -> Cantidades | F1: =Sopas!F1 -> Unidades
A2: Huevos escoceses | B2: 326 | C2: Calienta agua en un cazo, introduce en él los huevos de codorniz y cuécelos durante 4 minutos. Retíralos, refréscalos, pélalos y resérvalos. Corta la cebolla en daditos y ponla en un bol. Agrega las carnes, las yemas de huevo y la cucharada de pan rallado. Pela la manzana, rállala e incorpórala. Agrega también el kétchup y el jengibre rallado. Salpimienta y mezcla bien hasta que los ingredientes queden perfectamente integrados. Divide la mezcla en 8 porciones. Coge una porción de carne, extiéndela un poco, pon un huevo de codorniz en el centro y envuélvelo con la carne hasta taparlo y formar una albóndiga. Repite el proceso con el resto de la carne y de los huevos. Pásalos por harina, huevo y pan rallado y fríelos en una sartén con abundante aceite a fuego medio durante unos 5 minutos. Retíralos y escúrrelos sobre una fuente cubierta con papel absorbente. Aliña la escarola con aceite, vinagre y sal. Sirve en cada plato 2 huevos escoceses y una porción de escarola. Acompáñalos con la mostaza y adorna los platos con unas hojas de perejil. | D2: Huevos de codorniz | E2: 8 | F2: uds
D3: Carne picada | E3: 600 | F3: g
D4: Cebolla | E4: 0.5 | F4: uds
D5: Huevo | E5: 2 | F5: uds
D6: Pan rallado | E6: 1 | F6: uds
D7: Manzana | E7: 1 | F7: uds
D8: Kétchup | E8: 2 | F8: cuch
D9: Jengibre | E9: 15 | F9: g
D10: Mezcla rebozar | E10: 1 | F10: uds
D11: Mostaza | E11: 1 | F11: uds
D12: Vinagre | E12: 1 | F12: uds
D13: Perejil | E13: 1 | F13: uds
D14: Pimienta | E14: 1 | F14: uds
D15: Sal | E15: 1 | F15: uds
A16: Huevos napoleón | B16: 329 | C16: Corta el pan en dados, ponlos en una bandeja de horno y hornéalos a 220 ºC, hasta que se doren. Retíralos y resérvalos. Pela los dientes de ajo, pícalos y ponlos a dorar en una sartén con 3-4 cucharadas de aceite. Corta las cebolletas en juliana y añádelas. Retira el tallo y las semillas de los pimientos, córtalos en dados grandes y agrégalos. Sazona y cocina las hortalizas durante 10-15 minutos. Reparte en 4 recipientes aptos para el horno las hortalizas y, encima, los dados de pan tostados y el queso. Casca los huevos, pon 2 en cada recipiente y sazónalos. Introdúcelos en el horno a 180 ºC durante unos 8 minutos. Sirve y decora con unas hojas de perejil. | D16: Huevo | E16: 8 | F16: uds
D17: Rebanada de pan | E17: 8 | F17: uds
D18: Diente de ajo | E18: 2 | F18: uds
D19: Cebolla | E19: 2 | F19: uds
D20: Pimiento verde | E20: 2 | F20: uds
D21: Queso gratinar | E21: 200 | F21: g
D22: Aceite de oliva | E22: 1 | F22: uds
D23: Perejil | E23: 1 | F23: uds
D24: Sal | E24: 1 | F24: uds
A25: Rollitos de tortilla, queso y panceta | B25: 334 | C25: Pela el diente de ajo y la cebolla, córtalos en dados y ponlos a rehogar en una cazuela con 3-4 cucharadas de aceite. Retira el tallo y las semillas del pimiento, córtalo de la misma manera y agrégalo. Sazona y cocina las hortalizas durante 10 minutos. Agrega 250 ml de agua y deja que reduzca durante 10 minutos. Tritura los ingredientes con una batidora eléctrica hasta conseguir una salsa homogénea y resérvala. Casca 1 huevo, ponlo en un bol, sazónalo, añade un poco de perejil picado y bátelo. Calienta una sartén pequeña con unas gotas de aceite, vierte en ella el huevo y cuaja una tortilla (a modo de crepe). Repite el proceso con el resto de los huevos. Fríe las lonchas de panceta (sin que se doren) en una sartén con una gotita de aceite. Retíralas a un plato y resérvalas. Corta 8 bastones de queso y ralla el resto. Extiende las tortillas, pon 1 bastón de queso en uno de los lados de cada una y enróllalas alrededor. Envuelve cada tortilla con 1 loncha de panceta y coloca los rollitos sobre una bandeja o fuente apta para el horno. Espolvoréalos con el queso rallado y gratínalos en el horno hasta que se doren un poco. Sirve la salsa en el fondo de 4 platos y coloca encima 2 rollitos en cada uno. Adorna los platos con unas hojas de perejil. | D25: Huevo | E25: 8 | F25: uds
D26: Queso | E26: 250 | F26: g
D27: Lonchas panceta | E27: 8 | F27: uds
D28: Diente de ajo | E28: 1 | F28: uds
D29: Cebolla | E29: 1 | F29: uds
D30: Pimiento verde | E30: 4 | F30: uds
D31: Aceite de oliva | E31: 1 | F31: uds
D32: Perejil | E32: 1 | F32: uds
D33: Sal | E33: 1 | F33: uds
A34: Huevos teresita | B34: 340 | C34: Pon agua a calentar en un cazo, introduce los huevos y cuécelos durante 10 minutos desde el momento en que el agua empiece a hervir (para que las yemas queden centradas, remuévelos circularmente con una cuchara de madera). Retíralos, refréscalos, pélalos y córtalos por la mitad. Separa las yemas de las claras y resérvalas por separado. Calienta agua en una cazuela y, cuando empiece a hervir, agrega los guisantes. Sazónalos y cuécelos durante 10-15 minutos (según tamaño). Para el relleno, pela los ajos, pícalos, ponlos en el mortero y májalos bien. Añade las yemas, 1 cucharada de perejil picado y una pizca de sal. Maja de nuevo hasta conseguir una pasta homogénea (si queda muy seca, puedes añadir un poco de agua). Rellena las claras de huevo con el majado y dóralas (en tandas) boca abajo en una sartén con 2-3 cucharadas de aceite caliente. Cuando estén selladas, retíralas y resérvalas. Corta el jamón en daditos y ponlo a dorar en una tartera (cazuela amplia y baja) con 3 cucharadas de aceite. Cuando coja un poco de color, añade la harina, rehógala un poco y agrega el pimentón. Incorpora el caldo, los guisantes y los huevos (boca abajo). Tapa la tartera y cocínalos en la salsa durante 6-8 minutos. Con ayuda de un cortapastas redondo (pequeño), corta 4 círculos de cada rebanada de pan. Calienta abundante aceite en una sartén y fríe en él 1 rebanada de pan y 4 círculos por los 2 lados. Retíralos y escúrrelos sobre una fuente cubierta con papel absorbente. Repite el proceso con las otras 3 rebanadas de pan y los 12 círculos. Pon las rebanadas de pan en 4 platos, coloca las claras rellenas en los huecos y salsea. Adorna los platos con unas hojas de perejil y los círculos de pan frito. | D34: Huevo | E34: 8 | F34: uds
D35: Guisantes | E35: 100 | F35: g
D36: Diente de ajo | E36: 2 | F36: uds
D37: Jamón | E37: 100 | F37: g
D38: Harina | E38: 1 | F38: cuch
D39: Caldo de ave | E39: 300 | F39: mL
D40: Rebanada de pan | E40: 4 | F40: uds
...

Sheet Arroces
A1: =Sopas!A1 -> Plato | B1: Página | C1: Elaboración | D1: =Sopas!D1 -> Ingredientes | E1: =Sopas!E1 -> Cantidades | F1: =Sopas!F1 -> Unidades
A2: Arroz al horno | B2: 346 | C2: Lava los tomates, pela uno y córtalo en dados. Corta los otros 2 por la mitad. Calienta una tartera (cazuela amplia y plana) apta para el horno con 3 cucharadas de aceite. Añade los dados de tomate, la cabeza de ajos entera y los tomates cortados a la mitad y cocínalos durante 3-4 minutos. Pela las patatas, córtalas en rodajas de 1 cm, agrégalas y sazónalas. Incorpora el arroz y rehógalo brevemente. Añade los garbanzos, el caldo caliente, las hebras de azafrán y el pimentón. Sazona y cocina el arroz a fuego fuerte durante 6-8 minutos. Introduce la tartera en el horno y hornea el arroz a 200 ºC durante 12-14 minutos. Retira la tartera del horno y sirve. Adorna los platos con unas hojas de perejil. | D2: Arroz | E2: 300 | F2: g
D3: Tomate | E3: 3 | F3: uds
D4: Cabeza de ajos | E4: 1 | F4: uds
D5: Patata | E5: 2 | F5: uds
D6: Garbanzos | E6: 150 | F6: g
D7: Caldo de verduras | E7: 900 | F7: mL
D8: Aceite de oliva | E8: 1 | F8: uds
D9: Perejil | E9: 1 | F9: uds
D10: Azafrán | E10: 1 | F10: uds
D11: Pimentón | E11: 1 | F11: cuch
D12: Sal | E12: 1 | F12: uds
A13: Arroz con costilla de cerdo | B13: 352 | C13: Calienta agua en la olla y sazónala. Limpia el puerro (retírale la parte inferior, la superior y 1-2 capas y enjuágalo), trocéalo e introdúcelo en la olla. Agrega la costilla, cierra la olla y cuécela durante 10-15 minutos. Retírala, escúrrela y salpimiéntala. Calienta 3-4 cucharadas de aceite en una tartera (cazuela amplia y baja), añade los trozos de costilla y rehógala hasta que esté bien dorada. Retírala a un plato y resérvala. Pela la cebolleta, el pimiento rojo y los ajos, córtalos en daditos y agrégalos a la tartera. Sazona y cocina las hortalizas a fuego suave-medio durante 10-15 minutos. Incorpora el arroz y rehógalo brevemente. Añade el pimentón, la costilla y agua caliente (el doble y un poco más que de arroz) y cocina todo durante 20 minutos. Sirve el arroz y adorna los platos con unas hojas de perejil. | D13: Arroz | E13: 300 | F13: g
D14: Costilla de cerdo | E14: 600 | F14: g
D15: Puerro | E15: 1 | F15: uds
D16: Cebolla | E16: 1 | F16: uds
D17: Pimiento rojo | E17: 0.5 | F17: uds
D18: Diente de ajo | E18: 2 | F18: uds
D19: Aceite de oliva | E19: 1 | F19: uds
D20: Perejil | E20: 1 | F20: uds
D21: Pimienta | E21: 1 | F21: uds
D22: Pimentón | E22: 1 | F22: cuch
D23: Sal | E23: 1 | F23: uds
A24: Pasteles de arroz, zanahorias y panceta | B24: 352 | C24: Pon agua a hervir en una olla rápida, añade el arroz y sazónalo. Cierra la olla, cuécelo durante 5 minutos, escúrrelo y resérvalo. Pela las zanahorias y cuécelas durante 15 minutos en una cazuela con agua y una pizca de sal. Resérvalas. Pela la cebolla y los dientes de ajo, córtalos en dados y rehógalos durante 8-10 minutos a fuego suave en una sartén con 3 cucharadas de aceite. Corta la panceta en dados, añádela y cocínala hasta que se dore. Pon los huevos en un bol y bátelos. Agrega la leche y bate de nuevo. Incorpora las hortalizas con la panceta y el arroz y mezcla bien. Corta las zanahorias en rodajas y añádelas. Mezcla con cuidado, reparte la mezcla en 4 recipientes individuales aptos para el horno y hornéalos a 200 ºC durante 12 minutos. Sirve los pasteles y adórnalos con unas hojas de perejil. | D24: Arroz | E24: 200 | F24: g
D25: Zanahoria | E25: 6 | F25: uds
D26: Panceta | E26: 150 | F26: g
D27: Cebolla | E27: 1 | F27: uds
D28: Diente de ajo | E28: 2 | F28: uds
D29: Huevo | E29: 2 | F29: uds
D30: Leche | E30: 125 | F30: mL
D31: Aceite de oliva | E31: 1 | F31: uds
D32: Perejil | E32: 1 | F32: uds
D33: Sal | E33: 1 | F33: uds
A34: Croquetas de arroz con pollo y espinacas | B34: 353 | C34: Pela el diente de ajo, córtalo en daditos y dóralo en una cazuela con 3 cucharadas de aceite. Agrega el arroz y el agua (el doble y un poco más que de arroz), desmenuza encima la pastilla de caldo, mezcla y cocina el arroz durante 18-20 minutos. Deja que se enfríe. Calienta una sartén con 1 cucharada de aceite, sazona la pechuga, añádela a la sartén y dórala por los dos lados. Retira la pechuga, córtala en daditos y ponla en un bol grande. Limpia las hojas de espinacas, sécalas, pícalas finamente e introdúcelas en el bol. Agrega el arroz y mezcla todo bien. Casca un huevo, bátelo, incorpóralo al bol y mezcla de nuevo. Coge pequeñas porciones de masa, redondéalas, pásalas por harina y huevo batido y fríelas a fuego medio en una sartén con aceite. Escúrrelas sobre una fuente cubierta con papel absorbente. Calienta la salsa de tomate. Sirve en cada plato 5 croquetas y un poco de salsa de tomate. Adórnalos con unas hojas de perejil. | D34: Arroz | E34: 300 | F34: g
D35: Pechuga de pollo | E35: 100 | F35: g
D36: Espinacas | E36: 20 | F36: g
D37: Diente de ajo | E37: 1 | F37: uds
D38: Pastilla de caldo de pollo | E38: 1 | F38: uds
D39: Huevo | E39: 1 | F39: uds
D40: Mezcla rebozar | E40: 1 | F40: uds
...

Sheet Pastas
A1: =Sopas!A1 -> Plato | B1: Página | C1: Elaboración | D1: =Sopas!D1 -> Ingredientes | E1: =Sopas!E1 -> Cantidades | F1: =Sopas!F1 -> Unidades
A2: Canelones a la boloñesa | B2: 370 | C2: Calienta abundante agua en una cazuela. Cuando empiece a hervir, sazónala, introduce en ella los canelones y cuécelos durante el tiempo que indique el paquete. Retíralos, escúrrelos y colócalos sobre un paño limpio de cocina. Calienta 3-4 cucharadas de aceite en una cazuela. Pela los dientes de ajo, córtalos en daditos y agrégalos. Pela la cebolla, córtala en daditos y añádela. Retira el tallo y las semillas del pimiento, córtalo de la misma manera e incorpóralo. Pela las zanahorias, córtalas en cuartos de luna y agrégalas. Corta la rama de apio en daditos y añádela. Sazona y rehoga las hortalizas durante 10-12 minutos. Agrega las carnes picadas, salpimiéntalas y rehógalas un poco. Vierte encima el vino blanco y dale un hervor. Incorpora el tomate, mezcla y cocina la boloñesa durante 10-15 minutos. Rellena los canelones con la boloñesa y repártelos en 4 platos (o fuente) aptos para el horno. Para preparar la bechamel, funde la mantequilla en una cazuela, añade la harina y rehógala bien. Agrega la leche poco a poco sin dejar de remover hasta que los ingredientes queden bien integrados. Cocina la bechamel a fuego suave durante 8-10 minutos. Condiméntala con sal, una pizca de nuez moscada y el perejil picado. Cubre los canelones con la salsa bechamel, espolvorea encima el queso y gratínalos hasta que el queso se dore. Sirve y adorna los platos con unas hojas de perejil. | D2: Láminas para canelones | E2: 16 | F2: uds
D3: Carne picada | E3: 400 | F3: g
D4: Diente de ajo | E4: 2 | F4: uds
D5: Cebolla | E5: 1 | F5: uds
D6: Pimiento verde | E6: 1 | F6: uds
D7: Zanahoria | E7: 2 | F7: uds
D8: Apio | E8: 1 | F8: uds
D9: Vino blanco | E9: 125 | F9: mL
D10: Tomate triturado | E10: 250 | F10: mL
D11: Queso en polvo | E11: 50 | F11: g
D12: Aceite de oliva | E12: 1 | F12: uds
D13: Perejil | E13: 1 | F13: uds
D14: Pimienta | E14: 1 | F14: uds
... D21: Sal | E21: 1 | F21: uds
A22: Cintas con tomate y queso | B22: 374 | C22: Pon a calentar abundante agua en una cazuela. Lava los tomates, hazles un corte superficial en cruz por la parte inferior, introdúcelos en la cazuela y escáldalos durante 2 minutos. Retíralos, pélalos y córtalos en daditos. Pela los dientes de ajo y corta cada uno en 3 láminas. Elimina la parte inferior de los espárragos y córtalos en rodajas de 1 cm. Calienta una sartén grande con 3 cucharadas de aceite, agrega los ajos y los espárragos y cocínalos durante 3-5 minutos a fuego suave. Incorpora los tomates, sazónalos, cocínalos durante 15 minutos a fuego medio y espolvoréalos con el orégano. Calienta abundante agua en una cazuela. Cuando empiece a hervir, sazona el agua, introduce en ella las cintas y cuécelas durante el tiempo que indique el paquete. Retíralas e introdúcelas directamente en la sartén con las hortalizas. Mezcla bien y repártelas en 4 platos. Espolvorea los platos con el queso y adórnalos con unas hojas de perejil. | D22: Cintas de pasta | E22: 300 | F22: g
D23: Tomate | E23: 3 | F23: uds
D24: Queso parmesano | E24: 75 | F24: g
D25: Diente de ajo | E25: 2 | F25: uds
D26: Espárragos verdes | E26: 12 | F26: uds
D27: Aceite de oliva | E27: 1 | F27: uds
D28: Orégano | E28: 1 | F28: uds
D29: Perejil | E29: 1 | F29: uds
D30: Sal | E30: 1 | F30: uds
A31: Espirales con sofrito y anchoas | B31: 376 | C31: Calienta abundante agua en una cazuela grande. Cuando empiece a hervir, añade la pasta y sazona. Cuécela durante un poquito menos del tiempo que indique el paquete (debe quedar muy al dente). Calienta 3 cucharadas de aceite en una tartera (cazuela amplia y baja). Limpia los ajos tiernos (retirándoles la parte inferior, la superior y 1 capa de hojas), córtalos en rodajas de 1 cm, añádelos a la tartera y rehógalos a fuego suave durante 3-4 minutos. Incorpora el sofrito de tomate y cebolla a la tartera. Corta las hojas de albahaca en juliana fina y agrégalas. Corta 12 aceitunas por la mitad (reserva el resto) y añádelas. Cocina todo conjuntamente durante 8-10 minutos. Añade la pasta (escurrida) al sofrito, mezcla bien y cocina todo durante 2-3 minutos. Reparte la pasta en 4 platos y muele encima un poco de pimienta. Coloca, encima de cada uno, 4 filetes de anchoa y 4 aceitunas (si quieres dar un toque especial a tus platos, puedes enroscar los filetes de anchoa alrededor de las aceitunas). Adorna los platos con unas hojas de perejil. | D31: Espirales | E31: 400 | F31: g
D32: Sofrito de tomate y cebolla | E32: 700 | F32: g
D33: Filetes de anchoas | E33: 16 | F33: uds
D34: Ajos frescos | E34: 8 | F34: uds
D35: Aceitunas negras | E35: 1 | F35: uds
D36: Aceite de oliva | E36: 1 | F36: uds
D37: Albahaca | E37: 1 | F37: uds
D38: Perejil | E38: 1 | F38: uds
D39: Pimienta | E39: 1 | F39: uds
D40: Sal | E40: 1 | F40: uds
A41: Lasaña de hortalizas con queso | B41: 378 | C41: Calienta 6 cucharadas de aceite en una cazuela grande. Corta las cebolletas en daditos y agrégalas. Pela las zanahorias, córtalas en cuartos de luna finos y añádelas. Retira el tallo y las semillas del pimiento, pélalo, córtalo en daditos e incorpóralo. Sazona y rehoga las hortalizas durante 6-8 minutos. Lava el calabacín, córtalo en medias lunas finas y agrégalo. Retira la parte inferior de los champiñones, enjuágalos, sécalos, córtalos primero por la mitad y luego en láminas e introdúcelos en la cazuela. Sazona y cocina todo junto durante 10-12 minutos más. Pica los tomates deshidratados y añádelos. Agrega también el tomillo y cocina todo junto durante 6-8 minutos más. Pon a calentar en una cazuela grande abundante agua con una pizca de sal. Cuando empiece a hervir, introduce en ella las láminas de lasaña de una en una y cuécelas durante el tiempo que indique el paquete. Cuando estén cocidas, escúrrelas y extiéndelas sobre un trapo limpio para que se sequen bien. Para hacer la bechamel, pon a calentar el aceite en una cazuela, añade la harina y rehógala un poco. Vierte la leche poco a poco, sin dejar de remover, y cocina la salsa durante 6-8 minutos (no hace falta que quede muy espesa). Sazónala, rállale encima un poco de nuez moscada, añádele el perejil picado, mezcla y resérvala. Para montar la lasaña, coloca en la base de una fuente apta para el horno 3 láminas de lasaña, la mitad de las hortalizas, 3 láminas de lasaña, el resto de las hortalizas y 3 láminas de lasaña. Cúbrelas con la bechamel y vierte encima la salsa de tomate formando unas líneas. Ralla el queso y espolvorea con él toda la superficie de la lasaña. Introduce la lasaña en el horno y gratínala hasta que se caliente y se dore el queso. Corta la lasaña en porciones y decora los platos con unas hojas de perejil. | D41: Láminas de lasaña | E41: 9 | F41: uds
D42: Cebolleta | E42: 2 | F42: uds
D43: Zanahoria | E43: 2 | F43: uds
D44: Pimiento rojo | E44: 1 | F44: uds
D45: Calabacín | E45: 1 | F45: uds
D46: Champiñón | E46: 10 | F46: uds
...

Sheet Carnes
A1: =Sopas!A1 -> Plato | B1: Página | C1: Elaboración | D1: =Sopas!D1 -> Ingredientes | E1: =Sopas!E1 -> Cantidades | F1: =Sopas!F1 -> Unidades
A2: Albóndigas con tomate y puré de patata | B2: 400 | C2: Trocea la miga de pan y ponla en un bol grande. Vierte encima el vino y espera a que la miga quede bien empapada. Escúrrela sobre un colador y resérvala. Calienta agua en una cazuela y sazónala. Pela las patatas, trocéalas, introdúcelas en la cazuela y cuécelas durante 15-20 minutos. Escúrrelas y pásalas por el pasapurés (o aplástalas con un machacador de patatas) sobre un bol. Agrega la leche (caliente) poco a poco y mezcla suavemente. Salpimienta, añade un poco de perejil picado y vuelve a mezclar. Reserva el puré. Pon la carne picada (ternera y cerdo) en un bol. Pela 2 dientes de ajo, pícalos finamente (en daditos) y agrégalos junto con la yema y 1 cucharadita de perejil picado. Salpimienta y mezcla. Incorpora la miga de pan (escurrida) y sigue mezclando hasta que los ingredientes queden bien integrados. Forma bolitas, pásalas por harina y fríelas en una sartén con aceite. Pon a calentar el sofrito de tomate y cebolla en una cazuela baja, introduce en ella las albóndigas y cocínalas durante 5-6 minutos. Si ves que la salsa queda muy espesa, puedes aligerarla agregándole un poco de agua. Cubre el fondo de los platos con el puré de patata y sirve las albóndigas encima. Decóralos con unas hojas de perejil. | D2: Carne picada mixto | E2: 700 | F2: g
D3: Sofrito de tomate y cebolla | E3: 700 | F3: g
D4: Patata | E4: 4 | F4: uds
D5: Miga de pan | E5: 50 | F5: g
D6: Vino blanco | E6: 150 | F6: mL
D7: Leche | E7: 125 | F7: mL
D8: Diente de ajo | E8: 2 | F8: uds
D9: Yema de huevo | E9: 1 | F9: uds
D10: Harina | E10: 1 | F10: uds
D11: Aceite de oliva | E11: 1 | F11: uds
D12: Perejil | E12: 1 | F12: uds
D13: Pimienta | E13: 1 | F13: uds
D14: Sal | E14: 1 | F14: uds
A15: Albóndigas en salsa de almendras | B15: 402 | C15: Trocea la miga de pan y ponla en un bol. Vierte la leche y espera a que se empape bien. Pon las carnes (ternera y cerdo) en un bol y mézclalas. Pela 3 dientes de ajo, pícalos finamente y agrégalos. Añade también las yemas de huevo, 1 cucharada de perejil picado, el zumo de medio limón, la miga de pan escurrida, sal y pimienta (al gusto). Mezcla bien. Forma bolitas, pásalas por harina y fríelas en una sartén con 150 ml de aceite. Retíralas y resérvalas en una fuente. Cuela el aceite resultante de freír las albóndigas, pásalo a otra sartén, agrega las almendras, tuéstalas hasta que se doren y resérvalas en un plato. Pela la cebolla, córtala en dados, incorpórala a la sartén y rehógala durante 8-10 minutos. Lava los tomates, córtalos por la mitad y rállalos. Añade a la sartén la pulpa de los tomates, 1 cucharadita de azúcar, el comino, la pimienta y la hoja de laurel. Cocina los ingredientes durante 8-10 minutos. Incorpora las almendras y el vino blanco. Sazona y cocina todo durante 15 minutos a fuego suave. Retira la hoja de laurel y tritura los ingredientes en un vaso americano. Coloca las albóndigas en la sartén, vierte encima la salsa (si queda muy espesa, puedes aligerarla agregando un poco de agua caliente) y cocínalas durante 6-8 minutos. | D15: Carne picada mixto | E15: 700 | F15: g
D16: Miga de pan | E16: 100 | F16: g
D17: Leche | E17: 200 | F17: mL
D18: Diente de ajo | E18: 3 | F18: uds
D19: Yema de huevo | E19: 2 | F19: uds
D20: Limón | E20: 0.5 | F20: uds
D21: Harina | E21: 1 | F21: uds
D22: Aceite de oliva | E22: 1 | F22: uds
D23: Perejil | E23: 1 | F23: uds
D24: Pimienta | E24: 1 | F24: uds
D25: Sal | E25: 1 | F25: uds
D26: Almendra | E26: 150 | F26: g
D27: Cebolla | E27: 1 | F27: uds
... D35: Sal | E35: 1 | F35: uds
A36: Aleta rellena de pimientos y tortilla | B36: 404 | C36: Bate en un bol los huevos con una pizca de sal. Calienta una sartén con 1 cucharadita de aceite, vierte en ella los huevos y cuájalos por los dos lados hasta conseguir una tortilla fina. Retírala a un plato y resérvala. Extiende la aleta (abierta) sobre la tabla, salpimiéntala y coloca encima la tortilla y los pimientos (abiertos por la mitad). Sazona los pimientos, enrolla la aleta y átala con cuerda de cocina. Sazónala por fuera y dórala en una sartén con un chorrito de aceite durante 3-4 minutos. Pasa la aleta a una fuente apta para el horno. Pela los ajos, la cebolla y las zanahorias y córtalos en dados. Saltea las hortalizas durante 2 minutos en la misma sartén donde has dorado la carne. Agrega el vino y dale un hervor. Incorpora las hortalizas a la fuente con la aleta y hornea a 190-200 ºC durante 35-40 minutos. Retira la carne, deja que se temple, filetéala y resérvala. Pasa las hortalizas a un vaso batidor y tritúralas con una batidora eléctrica. Reserva la salsa. Limpia las coles de Bruselas (retirándoles las hojas exteriores) y córtalas por la mitad. Calienta una sartén con 3-4 cucharadas de aceite, añade las coles de Bruselas, sazónalas y cocínalas a fuego suave-medio durante 6-8 minutos. Sirve en cada plato 2 filetes de aleta, 4 coles de Bruselas (8 mitades) y un poco de salsa. Decora los platos con unas hojas de perejil. | D36: Aleta de ternera | E36: 1 | F36: uds
D37: Pimientos del piquillo | E37: 6 | F37: uds
D38: Huevo | E38: 3 | F38: uds
D39: Diente de ajo | E39: 2 | F39: uds
D40: Cebolla | E40: 1 | F40: uds
D41: Zanahoria | E41: 2 | F41: uds
D42: Coles de bruselas | E42: 24 | F42: uds
D43: Vino blanco | E43: 150 | F43: mL
D44: Aceite de oliva | E44: 1 | F44: uds
D45: Perejil | E45: 1 | F45: uds
D46: Pimienta | E46: 1 | F46: uds
D47: Sal | E47: 1 | F47: uds
...

Sheet Pescados
A1: =Sopas!A1 -> Plato | B1: Página | C1: Elaboración | D1: =Sopas!D1 -> Ingredientes | E1: =Sopas!E1 -> Cantidades | F1: =Sopas!F1 -> Unidades
A2: Bacalao a la riojana con guindillas fritas | B2: 529 | C2: Pela los ajos, córtalos en láminas y rehógalos en una sartén con 4-5 cucharadas de aceite. Pela las cebollas, córtalas en dados grandes y agrégalos. Pela los pimientos, retírales el tallo y las semillas, córtalos en dados grandes y añádelos a la sartén. Sazona y cocina las hortalizas durante unos 10 minutos. Lava los tomates, córtalos por la mitad, rállalos e incorpóralos a la sartén. Cocina todo durante 15-20 minutos. Corta cada lomo de bacalao en dos e introdúcelos en la sartén (primero dejando la parte de la piel hacia arriba). Cocínalos a fuego suave durante 5 minutos por cada lado. Fríe las guindillas en una sartén con aceite bien caliente. Retíralas a un plato y sazónalas. Sirve en cada plato un trozo de bacalao con su salsa y acompáñalos con las guindillas fritas. Decora los platos con unas hojas de perejil. | D2: Bacalao | E2: 800 | F2: g
D3: Guindillas | E3: 100 | F3: g
D4: Diente de ajo | E4: 4 | F4: uds
D5: Cebolla | E5: 2 | F5: uds
D6: Pimiento morrón | E6: 2 | F6: uds
D7: Tomate maduro | E7: 800 | F7: g
D8: Aceite de oliva | E8: 1 | F8: uds
D9: Perejil | E9: 1 | F9: uds
D10: Sal | E10: 1 | F10: uds
A11: Bacalao gratinado con mayonesa de ajo fresco | B11: 536 | C11: Mezcla en un bol 2 vasos de agua y el pimentón. Coloca las rebanadas de pan en una fuente honda, viérteles encima la mezcla de agua y pimentón y déjalas reposar hasta que hayan absorbido todo el líquido. Coloca cada rebanada entre dos platos y aplástalas hasta escurrirlas bien. Cubre una bandeja de horno con papel de hornear, extiende encima las rebanadas de pan, tápalas con otro trozo de papel de hornear y presiónalas colocándoles encima otra bandeja de horno. Hornéalas a 180º C durante 25-30 minutos. Retíralas y resérvalas. Pica 8 ajos frescos (reserva el resto) y cocínalos a fuego suave en una sartén con 4 cucharadas de aceite hasta que se ablanden (10 minutos aproximadamente), pásalos a un mortero y májalos bien hasta obtener una crema de ajo. Resérvala. Para preparar la mayonesa, casca el huevo, ponlo en un vaso batidor y agrega el vinagre, una pizca de sal y 250 ml de aceite. Introduce el brazo de la batidora hasta el fondo y empieza a batir sin mover el brazo. Cuando empiece a emulsionar, muévelo suavemente. Agrega la crema de ajo fresco con su aceite y sigue batiendo los ingredientes hasta conseguir una salsa homogénea. Reserva la mayonesa. Corta el bacalao en 8 trozos, aplástalos con un cuchillo (dándoles unos golpes), sazónalos, pásalos por la harina y fríelos brevemente (1 minuto por cada lado) en una sartén con 8 cucharadas de aceite caliente. Retíralos y colócalos en una bandeja de horno. Cubre cada trozo con un poco de mayonesa de ajo fresco y gratínalos durante 2-3 minutos (hasta que se doren). Limpia el resto de los ajetes, córtalos por la mitad y hazles dos cortes longitudinales sin llegar hasta el final (como se hace para limpiar los puerros). Mezcla la harina de tempura con agua bien fría (en la proporción que indique el paquete). Introduce los ajos en la mezcla y fríelos en una sartén con aceite bien caliente. Retíralos y escúrrelos sobre un plato cubierto con papel absorbente. Sirve en cada plato 2 trozos de bacalao, 4 ajos frescos en tempura y 1 rebanada de pan de pimentón. Adorna los platos con unas hojas de perejil. | D11: Bacalao | E11: 800 | F11: g
D12: Diente de ajo | E12: 24 | F12: uds
D13: Rebanada de pan | E13: 4 | F13: uds
D14: Huevo | E14: 1 | F14: uds
D15: Harina | E15: 1 | F15: uds
D16: Harina de tempura | E16: 175 | F16: g
D17: Aceite de oliva | E17: 1 | F17: uds
D18: Vinagre | E18: 1 | F18: cuch
D19: Perejil | E19: 1 | F19: uds
D20: Pimentón | E20: 1 | F20: cuch
D21: Sal | E21: 1 | F21: uds
A22: Brocheta de salmón con salsa de yogur | B22: 541 | C22: Pon a calentar suavemente el aceite en una sartén pequeña. Corta el tallo de la cebolleta en rodajas y añádelo. Pela el diente de ajo y agrégalo. Añade el tomillo, el eneldo y los granos de pimienta. Cocina los ingredientes a fuego muy suave durante 10-12 minutos. Retira la sartén del fuego y deja templar. Cuela el aceite sobre un recipiente grande rectangular. Limpia el salmón, córtalo en 16 dados grandes y pínchalos, de 4 en 4, en 4 palillos de brocheta. Introduce las brochetas en el recipiente y úntalas bien en el aceite. Déjalas macerando por lo menos durante 1 hora (mejor si se dejan desde la víspera). Para preparar la salsa de yogur, pela la chalota, córtala en daditos y ponla en un bol. Añade la mayonesa, el yogur, unas gotas de zumo de limón, una pizca de sal y la mitad de las hojas de cebollino finamente picadas. Calienta una plancha, coloca en ella las brochetas de salmón y cocínalas durante 1-2 minutos por cada lado (según os guste el punto). Retíralas y salpimiéntalas. Sirve una brocheta por ración y acompáñalas con la salsa de yogur. Pica el resto de las hojas de cebollino y espolvorea con ellas la salsa. Decora los platos con unas hojas de perejil. | D22: Salmón | E22: 800 | F22: g
D23: Cebolleta | E23: 1 | F23: uds
D24: Diente de ajo | E24: 1 | F24: uds
D25: Aceite de oliva | E25: 175 | F25: mL
D26: Tomillo | E26: 2 | F26: uds
D27: Eneldo | E27: 6 | F27: uds
D28: Perejil | E28: 1 | F28: uds
D29: Pimienta | E29: 1 | F29: uds
D30: Sal | E30: 1 | F30: uds
D31: Yogur natural | E31: 1 | F31: uds
D32: Chalota | E32: 1 | F32: uds
D33: Mayonesa | E33: 1 | F33: cuch
D34: Limón | E34: 0.5 | F34: uds
... D36: Sal | E36: 1 | F36: uds
A37: Bacalao fresco con cuscús | B37: 548 | C37: Pon las espinas del bacalao, los tallos del hinojo y unas ramas de perejil en una cazuela con 500 ml de agua. Sazona y cuece todo durante 10 minutos. Cuela el caldo y resérvalo. Pela la cebolleta y la zanahoria, córtalas en dados y ponlas a rehogar en una cazuela con 3 cucharadas de aceite. Corta el hinojo de la misma manera y agrégalo. Sazona y rehoga las hortalizas durante unos 10-12 minutos. Incorpora el cuscús y agrega la misma cantidad de caldo (reserva el resto) que de cuscús. Tapa la cazuela, retírala del fuego y deja que el cuscús absorba el líquido. Añade un poco de perejil picado. Pon el resto del caldo en una cazuela. Salpimienta los lomos de bacalao, colócalos en una vaporera y ponla sobre la cazuela. Tápala y cocina el pescado durante 6-8 minutos. Con ayuda de un molde, reparte el cuscús en 4 platos, coloca encima los trozos de bacalao y aderézalos con un chorrito de aceite. Decora los platos con unas hojitas de hinojo. | D37: Bacalao | E37: 800 | F37: g
D38: Cuscús precocido | E38: 120 | F38: g
D39: Hinojo | E39: 0.25 | F39: uds
D40: Cebolleta | E40: 1 | F40: uds
D41: Zanahoria | E41: 1 | F41: uds
...

Sheet Postres
A1: =Sopas!A1 -> Plato | B1: Página | C1: Elaboración | D1: =Sopas!D1 -> Ingredientes | E1: =Sopas!E1 -> Cantidades | F1: =Sopas!F1 -> Unidades
A2: Flan de chocolate con nata | B2: 618 | C2: Para hacer el caramelo, pon el azúcar a calentar en una sartén. Espera a que se funda y se tueste un poco. Viértelo en una flanera (con tapa) y extiéndelo (con cuidado de no quemarte) por el fondo y la parte inferior de las paredes de la flanera. Deja que se enfríe un poco. Casca los huevos, ponlos en un bol, agrega la leche condensada y bate bien con una varilla manual. Pon el cacao y la leche en un vaso batidor y tritúralos con una batidora eléctrica. Añade la leche con cacao al bol de los huevos con leche condensada y mezcla bien. Pasa la mezcla a la flanera y ponle la tapa. Vierte un poco de agua (2 dedos) en una olla rápida, introduce en ella la flanera y cocina el flan durante 4 minutos. Cuando baje la válvula, abre la olla, retira el flan y espera a que se temple. Desmóldalo y sirve. Decóralo con la nata montada, las frambuesas y las hojas de menta. | D2: Huevo | E2: 4 | F2: uds
D3: Leche condensada | E3: 4 | F3: cuch
D4: Cacao en polvo | E4: 50 | F4: g
D5: Leche | E5: 500 | F5: mL
D6: Azúcar | E6: 100 | F6: g
D7: Nata montada | E7: 150 | F7: g
D8: Frambuesas | E8: 15 | F8: uds
D9: Menta | E9: 1 | F9: uds
A10: Tarta de galletas y chocolate con macadamia | B10: 622 | C10: Extiende una tira de papel de hornear a lo largo de un molde rectangular (tipo bizcocho) de manera que sobresalga una pestaña por cada lado. Extiende las galletas en una fuente grande, vierte encima la leche, ralla sobre ellas un poco de la piel de la naranja y deja que se empapen bien. Pon la nata a calentar en un cazo. Agrega el chocolate troceado y mezcla suavemente hasta que se funda. Apaga el fuego, incorpora el queso y remueve hasta que quede integrado en la mezcla. Cubre la base del molde con parte de la crema de chocolate, nata y queso. Extiende encima 5 galletas, cúbrelas con otro poco de crema de chocolate y tápala con otra capa de galletas. Repite el proceso hasta acabar con todos los ingredientes (finaliza con 6 galletas). Tapa la tarta con film transparente, introdúcela en el frigorífico y déjala enfriando por lo menos durante 2 horas. Bordea la tarta con una puntilla y desmóldala. Decórala con las frambuesas y las nueces de macadamia ralladas. Adorna con unas hojas de menta y sirve. | D10: Galletas rectangulares | E10: 210 | F10: g
D11: Chocolate de cobertura | E11: 340 | F11: g
D12: Nueces de macadamia | E12: 30 | F12: g
D13: Naranja | E13: 1 | F13: uds
D14: Nata | E14: 200 | F14: mL
D15: Queso cremoso | E15: 200 | F15: g
D16: Frambuesas | E16: 16 | F16: uds
D17: Menta | E17: 1 | F17: uds
A18: Palmeritas de chocolate | B18: 628 | C18: Extiende el hojaldre sobre la encimera, espolvoréalo con un poco de azúcar y pásale el rodillo suavemente por encima. Dale la vuelta, espolvoréalo con otro poco de azúcar y vuelve a pasarle el rodillo. Enrolla el hojaldre por uno de los extremos (largos) hasta llegar al centro. Haz lo mismo con el otro extremo, hasta que los dos rollos se junten en el centro. Corta el hojaldre en rodajas de unos 2 cm, extiéndelas sobre una bandeja de horno cubierta con papel de hornear y hornéalas a 190 ºC durante 20 minutos. Retira las palmeritas y deja que se enfríen sobre una rejilla. Funde por separado los chocolates, bien en el microondas o al baño maría. Introduce un lado de las palmeritas en el chocolate negro, extiéndelas sobre una fuente grande y espera a que el chocolate se solidifique. Introduce el otro lado de las palmeritas en el chocolate blanco y espera a que se solidifique (para que el chocolate se enfríe antes, puedes introducir las palmeritas en el frigorífico). Sirve y adorna los platos con unas hojas de menta. | D18: Lámina hojaldre | E18: 1 | F18: uds
D19: Chocolate negro de cobertura | E19: 125 | F19: g
D20: Chocolate blanco de cobertura | E20: 125 | F20: g
D21: Azúcar | E21: 50 | F21: g
D22: Menta | E22: 1 | F22: uds
A23: Mousse de fresa | B23: 632 | C23: Lava las fresas, retírales el tallo, trocéalas, ponlas en el vaso batidor y tritúralas con una batidora eléctrica hasta conseguir un puré homogéneo. Resérvalo. Pon el queso en un bol grande y bátelo con una batidora de varillas eléctrica. Añade el azúcar (en tres veces) y bátelo. Incorpora la nata (en 3 veces) y bátela. Incorpora el puré de fresas (reserva un poco para decorar) poco a poco y bate la mezcla hasta que los ingredientes queden bien integrados. Tapa el bol con film transparente, introdúcelo en el frigorífico y deja que se enfríe. Sirve la mousse en 4 copas y decóralas con el puré de fresas reservado y unas hojas de menta. | D23: Fresas | E23: 500 | F23: g
D24: Queso mascarpone | E24: 100 | F24: g
D25: Azúcar glas | E25: 50 | F25: g
D26: Nata | E26: 150 | F26: mL
D27: Menta | E27: 1 | F27: uds
A28: Peras al vino con yogur | B28: 633 | C28: Pon a calentar en una cazuela 200 ml de agua, el vino, la rama de canela y el azúcar a fuego suave. Pela las peras, introdúcelas en la cazuela, tapa y cuécelas a fuego suave durante 25-30 minutos dándoles la vuelta de vez en cuando (cada 5 minutos aprox.). Retira las peras y resérvalas en un plato. Pon el vino a reducir (sin tapa) y cocínalo a fuego suave hasta que reduzca a la mitad. Para que espese un poco más, deja que se enfríe. Sirve medio yogur en el fondo de cada plato, coloca encima las peras y salséalas con la reducción de oporto. Adorna las peras con unas hojas de menta. | D28: Peras | E28: 4 | F28: uds
D29: Vino de oporto | E29: 400 | F29: mL
D30: Yogur natural | E30: 2 | F30: uds
D31: Azúcar | E31: 2 | F31: cuch
D32: Canela | E32: 1 | F32: uds
D33: Menta | E33: 1 | F33: uds
A34: Tarta de arándanos | B34: 634 | C34: Para hacer la pasta quebrada, mezcla la harina, la sal, la levadura y el azúcar en un bol grande. Incorpora la mantequilla y mezcla un poco. Agrega el huevo y mezcla otro poco. Pasa la masa a la encimera y amásala hasta que los ingredientes queden bien integrados. Divide la masa en dos porciones, envuélvelas con film transparente, introdúcelas en el frigorífico y déjalas enfriar durante 2 horas (como mínimo) para que endurezca. Retíralas del frigorífico y amásalas suavemente hasta que se ablanden un poco. Espolvorea la encimera con un poco de harina, coloca encima una de las porciones de masa, estírala bien con un rodillo y cubre con ella un molde de fondo desmontable de 23 cm de diámetro. Para el relleno, mezcla en un bol la harina de maíz con el azúcar y la canela. Incorpora los arándanos y vuelve a mezclar. Añade el zumo de limón y mezcla de nuevo. Pon el relleno sobre la base de la tarta y dobla los bordes sobrantes hacia el centro. Espolvorea la encimera con otro poco de harina, coloca sobre ella la otra porción de pasta quebrada y estírala bien. Corta tiras largas de 2 cm de grosor y colócalas sobre la tarta formando un enrejado (tiras entrecruzadas). Bate la yema de huevo y, con ayuda de un pincel de cocina, pinta el enrejado. Coloca la tarta sobre la rejilla del horno (pon debajo una placa por si soltara algo de líquido) y hornéala a 200 ºC durante 40 minutos. Retírala del horno, espera a que se enfríe y desmóldala. Pon el azúcar glas en un colador y espolvorea con él la tarta. Adórnala con unas hojas de menta. | D34: Harina | E34: 400 | F34: g
D35: Sal | E35: 5 | F35: g
D36: Levadura | E36: 8 | F36: g
D37: Azúcar | E37: 100 | F37: g
D38: Mantequilla | E38: 180 | F38: g
D39: Huevo | E39: 1 | F39: uds
D40: Arándanos | E40: 500 | F40: g
...

Sheet Panes
A1: =Sopas!A1 -> Plato | B1: Página | C1: Elaboración | D1: =Sopas!D1 -> Ingredientes | E1: =Sopas!E1 -> Cantidades | F1: =Sopas!F1 -> Unidades
A2: Focaccia | B2: 20 | C2: La víspera, prepara la masa: pon la harina, la leche, la yema de huevo, la miel, la sal y la levadura desmenuzada en un bol y mezcla los ingredientes hasta que la harina esté bien integrada. Tapa el bol con film transparente y deja que repose durante 30 minutos a temperatura ambiente (autólisis). Espolvorea la encimera con un poco de harina, pon encima la masa, extiéndela un poco y agrega la mantequilla. Amasa (envolviendo la mantequilla con la masa) hasta que la mantequilla quede bien integrada. Pon un poco de aceite en la base de un bol grande, pon encima la masa, tápala con film transparente y deja que repose en el frigorífico durante 24 horas. Espolvorea la encimera con un poco de harina, saca la masa del frigorífico y extiéndela sobre la encimera (primero, con las manos, y después, con un rodillo) hasta conseguir un rectángulo. Colócalo sobre una bandeja de horno cubierta con papel de hornear. Distribuye encima las aceitunas (cortadas en aros) y los tomates (cortados por la mitad). Tapa la masa con un paño limpio y deja que repose hasta que doble su volumen (1 hora aprox.). Mezcla en un bol pequeño el aceite con 2 cucharadas de agua, 1 rama de romero (picada) y una pizca de sal. Presiona la masa con los dedos, úntala bien con el aceite de romero y salpícala con la flor de sal. Calienta el horno a 230 ºC. Baja la temperatura a 190 ºC, introduce la focaccia y hornéala a 190 ºC durante 12-15 minutos. Retírala del horno y deja que se enfríe un poco. Sirve y adorna los platos con unas hojas de perejil y unos trocitos de rama de romero. | D2: Aceitunas | E2: 12 | F2: uds
D3: Tomates cherry | E3: 6 | F3: uds
D4: Aceite de oliva | E4: 2 | F4: cuch
D5: Romero | E5: 2 | F5: uds
D6: Sal | E6: 1 | F6: uds
D7: Perejil | E7: 1 | F7: uds
D8: Harina | E8: 275 | F8: g
D9: Leche | E9: 125 | F9: mL
D10: Yema de huevo | E10: 1 | F10: uds
D11: Miel | E11: 12 | F11: g
D12: Sal | E12: 5 | F12: g
D13: Levadura | E13: 8 | F13: g
D14: Mantequilla | E14: 35 | F14: g
D15: Aceite de oliva | E15: 1 | F15: uds
